<?xml version="1.0"?>
<robot name="robot3links">
  <link name="base link">
    <inertial>
      <mass value="200.0"/>
      <inertia ixx="0" ixy="0" ixz="0" iyy="0" iyz="0" izz="0"/>
    </inertial>

    <visual>
      <origin rpy="0 0 0" xyz="0.0 0.0 0.15"/>
      <geometry>
        <box size="0.75 0.75 0.3"/>
      </geometry>
      <material name="white">
        <color rgba="1 1 1 1"/>
      </material>
    </visual>

    <collision>
      <origin rpy="0 0 0" xyz="0.0 0.0 0.15"/>
      <geometry>
        <box size="0.75 0.75 0.3"/>
      </geometry>
    </collision>
  </link>

  <link name="body link">
    <inertial>
      <mass value="20.0"/>
      <inertia ixx="0" ixy="0" ixz="0" iyy="0" iyz="0" izz="0"/>
    </inertial>

    <visual>
      <origin rpy="0 0 0" xyz="0.0 0.0 0.8"/>
      <geometry>
        <box size="0.2 0.2 1.6"/>
      </geometry>
      <material name="blue">
        <color rgba="0 0 1 1"/>
      </material>
    </visual>

    <collision>
      <origin rpy="0 0 0" xyz="0.0 0.0 0.8"/>
      <geometry>
        <box size="0.2 0.2 1.6"/>
      </geometry>
    </collision>
  </link>


  <joint name="joint1" type="fixed">
      <origin xyz="0 0 0.3" rpy="0 0 0"/>
      <parent link="base link"/>
      <child link="body link"/>
   </joint>


   <link name="top link">
    <inertial>
      <mass value="5.0"/>
      <inertia ixx="0" ixy="0" ixz="0" iyy="0" iyz="0" izz="0"/>
    </inertial>

    <visual>
      <origin rpy="0 0 0" xyz="0.3 0.0 0.1"/>
      <geometry>
        <box size="0.8 0.2 0.2"/>
      </geometry>
      <material name="blue">
        <color rgba="0 0 1 1"/>
      </material>
    </visual>

    <collision>
      <origin rpy="0 0 0" xyz="0.3 0.0 0.1"/>
      <geometry>
        <box size="0.8 0.2 0.2"/>
      </geometry>
    </collision>
  </link>


  <joint name="joint2" type="revolute">
      <origin xyz="0.0 0 1.6" rpy="0 0 0"/>
      <parent link="body link"/>
      <child link="top link"/>
      <axis xyz="0.0 0 1"/>

      <calibration rising="0.0"/>
      <dynamics damping="0.0" friction="0.0"/>
      <limit effort="10" velocity="1.0" lower="-3.14" upper="3.14" />
   </joint>

 
</robot>
